{"uuid": "e092ed42-0e9d-4f09-b465-1324c15ca8d8", "children": ["34e0a0b4-4dad-402b-a136-9e78a555d17c"], "befores": [{"name": "create", "status": "broken", "statusDetails": {"message": "selenium.common.exceptions.NoSuchWindowException: Message: no such window: target window already closed\nfrom unknown error: web view not found\n  (Session info: chrome=84.0.4147.135)\n\n", "trace": "  File \"D:\\anaconda\\lib\\site-packages\\pluggy\\callers.py\", line 187, in _multicall\n    res = hook_impl.function(*args)\n  File \"D:\\anaconda\\lib\\site-packages\\_pytest\\fixtures.py\", line 964, in pytest_fixture_setup\n    result = call_fixture_func(fixturefunc, request, kwargs)\n  File \"D:\\anaconda\\lib\\site-packages\\_pytest\\fixtures.py\", line 792, in call_fixture_func\n    res = fixturefunc(**kwargs)\n  File \"D:\\pytst\\testcase\\Test_ayx.py\", line 24, in create\n    Create.get_url(ini.url)\n  File \"D:\\pytst\\page\\basepage.py\", line 57, in get_url\n    self.driver.maximize_window()\n  File \"D:\\anaconda\\lib\\site-packages\\selenium\\webdriver\\remote\\webdriver.py\", line 737, in maximize_window\n    self.execute(command, params)\n  File \"D:\\anaconda\\lib\\site-packages\\selenium\\webdriver\\remote\\webdriver.py\", line 321, in execute\n    self.error_handler.check_response(response)\n  File \"D:\\anaconda\\lib\\site-packages\\selenium\\webdriver\\remote\\errorhandler.py\", line 242, in check_response\n    raise exception_class(message, screen, stacktrace)\n"}, "start": 1597892137479, "stop": 1597892137480}], "start": 1597892137479, "stop": 1597892137516}