{"uuid": "1504260e-f7fe-44c9-861e-7857067ac75d", "children": ["67cff1bb-a578-45c3-9f2e-125945f774e3"], "befores": [{"name": "create", "status": "broken", "statusDetails": {"message": "selenium.common.exceptions.NoSuchWindowException: Message: no such window: target window already closed\nfrom unknown error: web view not found\n  (Session info: chrome=84.0.4147.135)\n\n", "trace": "  File \"D:\\anaconda\\lib\\site-packages\\pluggy\\callers.py\", line 187, in _multicall\n    res = hook_impl.function(*args)\n  File \"D:\\anaconda\\lib\\site-packages\\_pytest\\fixtures.py\", line 964, in pytest_fixture_setup\n    result = call_fixture_func(fixturefunc, request, kwargs)\n  File \"D:\\anaconda\\lib\\site-packages\\_pytest\\fixtures.py\", line 792, in call_fixture_func\n    res = fixturefunc(**kwargs)\n  File \"D:\\pytst\\testcase\\Test_BD.py\", line 23, in create\n    bd.get_url(ini.bdurl)\n  File \"D:\\pytst\\page\\basepage.py\", line 57, in get_url\n    self.driver.maximize_window()\n  File \"D:\\anaconda\\lib\\site-packages\\selenium\\webdriver\\remote\\webdriver.py\", line 737, in maximize_window\n    self.execute(command, params)\n  File \"D:\\anaconda\\lib\\site-packages\\selenium\\webdriver\\remote\\webdriver.py\", line 321, in execute\n    self.error_handler.check_response(response)\n  File \"D:\\anaconda\\lib\\site-packages\\selenium\\webdriver\\remote\\errorhandler.py\", line 242, in check_response\n    raise exception_class(message, screen, stacktrace)\n"}, "start": 1597892137438, "stop": 1597892137439}], "start": 1597892137438, "stop": 1597892137472}